Workbook

Sheet Dashboard_V5
A1: GPA ANGOLA – DASHBOARD COMERCIAL V5.0 SIMPLES E AUTOMATIZADO
A3: Comparativo correcto: 06–10 de Julho vs 13–17 de Julho de 2026 | Metas semanais
A5: Propostas | C5: Valor Total | E5: Aprovado | G5: Pipeline Aberto | I5: Forecast | K5: Conversão
A6: =COUNTIF(Base_Duas_Semanas!$A$4:$A$464,"Semana Finda") -> 32 | C6: =SUMIF(Base_Duas_Semanas!$A$4:$A$464,"Semana Finda",Base_Duas_Semanas!$G$4:$G$464) -> 2.6345043e+08 | E6: =SUMIF(Base_Duas_Semanas!$A$4:$A$464,"Semana Finda",Base_Duas_Semanas!$H$4:$H$464) -> 26762350 | G6: =SUMIFS(Base_Duas_Semanas!$G$4:$G$464,Base_Duas_Semanas!$A$4:$A$464,"Semana Finda",Base_Duas_Semanas!$S$4:$S$464,"Aberto") -> 2.2497601e+08 | I6: =SUMIF(Base_Duas_Semanas!$A$4:$A$464,"Semana Finda",Base_Duas_Semanas!$P$4:$P$464) -> 1.2311572e+08 | K6: =IFERROR(E6/C6,0) -> 0.10158401
A10: Indicador | B10: 06–10 Jul | C10: 13–17 Jul
A11: Valor total | B11: =Comparativo!B6 -> 1.5028229e+08 | C11: =Comparativo!C6 -> 2.6345043e+08
A12: Aprovado | B12: =Comparativo!B7 -> 19914950 | C12: =Comparativo!C7 -> 26762350
A13: =Comparativo!A8 -> Valor perdido | B13: =Comparativo!B8 -> 11779700 | C13: =Comparativo!C8 -> 11712075
A14: Forecast | B14: =Comparativo!B9 -> 76353142 | C14: =Comparativo!C9 -> 1.2311572e+08
A15: Propostas | B15: =Comparativo!B5 -> 29 | C15: =Comparativo!C5 -> 32
A18: Estado | B18: Valor
A19: Proposta enviada | B19: =SUMIFS(Base_Duas_Semanas!$G$4:$G$464,Base_Duas_Semanas!$A$4:$A$464,"Semana Finda",Base_Duas_Semanas!$F$4:$F$464,A19) -> 1.9438542e+08
A20: Proposta em negociação | B20: =SUMIFS(Base_Duas_Semanas!$G$4:$G$464,Base_Duas_Semanas!$A$4:$A$464,"Semana Finda",Base_Duas_Semanas!$F$4:$F$464,A20) -> 30590589
A21: Proposta aprovada | B21: =SUMIFS(Base_Duas_Semanas!$G$4:$G$464,Base_Duas_Semanas!$A$4:$A$464,"Semana Finda",Base_Duas_Semanas!$F$4:$F$464,A21) -> 26762350
A22: Produção / Entrega | B22: =SUMIFS(Base_Duas_Semanas!$G$4:$G$464,Base_Duas_Semanas!$A$4:$A$464,"Semana Finda",Base_Duas_Semanas!$F$4:$F$464,A22) -> 0
A23: Perdida | B23: =SUMIFS(Base_Duas_Semanas!$G$4:$G$464,Base_Duas_Semanas!$A$4:$A$464,"Semana Finda",Base_Duas_Semanas!$F$4:$F$464,A23) -> 11712075
A26: Comercial | B26: Meta Semanal | C26: Aprovado | D26: % Meta
A27: Amélia Cassinda | B27: =VLOOKUP(A27,Metas_Performance!$A$5:$C$11,3,FALSE) -> 6250000 | C27: =SUMIFS(Base_Duas_Semanas!$H$4:$H$464,Base_Duas_Semanas!$A$4:$A$464,"Semana Finda",Base_Duas_Semanas!$K$4:$K$464,A27) -> 4363350 | D27: =IFERROR(C27/B27,0) -> 0.698136
A28: David Guedes | B28: =VLOOKUP(A28,Metas_Performance!$A$5:$C$11,3,FALSE) -> 3750000 | C28: =SUMIFS(Base_Duas_Semanas!$H$4:$H$464,Base_Duas_Semanas!$A$4:$A$464,"Semana Finda",Base_Duas_Semanas!$K$4:$K$464,A28) -> 0 | D28: =IFERROR(C28/B28,0) -> 0
A29: Fernando Leite | B29: =VLOOKUP(A29,Metas_Performance!$A$5:$C$11,3,FALSE) -> 2500000 | C29: =SUMIFS(Base_Duas_Semanas!$H$4:$H$464,Base_Duas_Semanas!$A$4:$A$464,"Semana Finda",Base_Duas_Semanas!$K$4:$K$464,A29) -> 444600 | D29: =IFERROR(C29/B29,0) -> 0.17784
A30: José Neto | B30: =VLOOKUP(A30,Metas_Performance!$A$5:$C$11,3,FALSE) -> 5000000 | C30: =SUMIFS(Base_Duas_Semanas!$H$4:$H$464,Base_Duas_Semanas!$A$4:$A$464,"Semana Finda",Base_Duas_Semanas!$K$4:$K$464,A30) -> 0 | D30: =IFERROR(C30/B30,0) -> 0
A31: Marta de Oliveira | B31: =VLOOKUP(A31,Metas_Performance!$A$5:$C$11,3,FALSE) -> 6250000 | C31: =SUMIFS(Base_Duas_Semanas!$H$4:$H$464,Base_Duas_Semanas!$A$4:$A$464,"Semana Finda",Base_Duas_Semanas!$K$4:$K$464,A31) -> 9826550 | D31: =IFERROR(C31/B31,0) -> 1.572248
A32: Ilídio Pedro | B32: =VLOOKUP(A32,Metas_Performance!$A$5:$C$11,3,FALSE) -> 2500000 | C32: =SUMIFS(Base_Duas_Semanas!$H$4:$H$464,Base_Duas_Semanas!$A$4:$A$464,"Semana Finda",Base_Duas_Semanas!$K$4:$K$464,A32) -> 7977150 | D32: =IFERROR(C32/B32,0) -> 3.19086
A33: Luísa Baltazar | B33: =VLOOKUP(A33,Metas_Performance!$A$5:$C$11,3,FALSE) -> 7500000 | C33: =SUMIFS(Base_Duas_Semanas!$H$4:$H$464,Base_Duas_Semanas!$A$4:$A$464,"Semana Finda",Base_Duas_Semanas!$K$4:$K$464,A33) -> 4150700 | D33: =IFERROR(C33/B33,0) -> 0.55342667
A41: RECOMENDAÇÕES DE CRM – PRÓXIMA SEMANA
A42: 1 | B42: Fecho prioritário | C42: Negociações de prioridade Alta e propostas ≥ 10 M AOA | D42: Contacto directo ao decisor em 48 horas
A43: 2 | B43: Recuperação | C43: Propostas abertas com maior antiguidade | D43: Solicitar decisão formal ou rever condições
A44: 3 | B44: Produção e entrega | C44: Processos aprovados | D44: Confirmar artes, produção, entrega e facturação
A45: 4 | B45: Gestão da equipa | C45: Comerciais abaixo de 60% da meta | D45: Plano diário de contactos e apoio do Director Comercial
A46: 5 | B46: Controlo | C46: CRM_Proxima_Semana | D46: Actualizar acompanhamento: Pendente, Em curso, Concluído ou Reagendado

Sheet Base_Duas_Semanas
A1: Semana | B1: ID | C1: Data envio | D1: Cliente | E1: Serviço | F1: Estado proposta | G1: Valor proposta | H1: Valor aprovado | I1: Valor perdido | J1: Probabilidade | K1: Gestor comercial | L1: Próxima acção | M1: Próximo contacto | N1: Observações | O1: Dias em aberto | P1: Valor ponderado | Q1: Classe cliente | R1: Prioridade | S1: Estado CRM | T1: Meta semanal | U1: % Meta | V1: Resultado acompanhamento
A2: Semana Anterior | B2: 1 | C2: 46212 | D2: IMOCASAIS | E2: Fornecimento de Blocos de nota, canetas Flyers | F2: Proposta em negociação | G2: 1385100 | H2: 0 | I2: 0 | J2: 0.4 | K2: Luísa Baltazar | L2: Entragar em contacto com o cliente para saber o orçamento deles | M2: 46216 | N2: Proposta remetida para avaliação | O2: =IF(C2="","",MAX(0,TODAY()-C2)) -> 47 | P2: =IF(OR(G2="",J2=""),"",G2*J2) -> 554040 | Q2: B | R2: Normal | S2: Aberto | T2: =IF(K2="","",IFERROR(VLOOKUP(K2,Listas!$G$2:$J$8,4,FALSE),0)) -> 7500000 | U2: =IFERROR(H2/T2,0) -> 0
A3: Semana Anterior | B3: 2 | C3: 46210 | D3: SUEZ | E3: Fornecimento de Flyers monofolha e tripticos | F3: Proposta em negociação | G3: 6260880 | H3: 0 | I3: 0 | J3: 0.8 | K3: Luísa Baltazar | L3: negociar a modadlidade de pagamento | M3: 46216 | N3: Falta o envio da PO, para credibilizar a adjudicação do processo | O3: =IF(C3="","",MAX(0,TODAY()-C3)) -> 49 | P3: =IF(OR(G3="",J3=""),"",G3*J3) -> 5008704 | Q3: C | R3: Alta | S3: Aberto | T3: =IF(K3="","",IFERROR(VLOOKUP(K3,Listas!$G$2:$J$8,4,FALSE),0)) -> 7500000 | U3: =IFERROR(H3/T3,0) -> 0
A4: Semana Anterior | B4: 3 | C4: 46209 | D4: TEIXERA DUARTE | E4: Fornecimento de Diversos | F4: Proposta aprovada | G4: 758100 | H4: 758100 | I4: 0 | J4: 1 | K4: Luísa Baltazar | L4: Aumentar o fluxo de trabalhos com este cliente | M4: 46216 | N4: As artes já foram aprovadas | O4: =IF(C4="","",MAX(0,TODAY()-C4)) -> 50 | P4: =IF(OR(G4="",J4=""),"",G4*J4) -> 758100 | Q4: A | R4: Alta | S4: Fechado ganho | T4: =IF(K4="","",IFERROR(VLOOKUP(K4,Listas!$G$2:$J$8,4,FALSE),0)) -> 7500000 | U4: =IFERROR(H4/T4,0) -> 0.10108
A5: Semana Anterior | B5: 4 | C5: 46210 | D5: SIAC | E5: Fornecimento de brindes e merchandising | F5: Proposta enviada | G5: 19418760 | H5: 0 | I5: 0 | J5: 0.4 | K5: Luísa Baltazar | L5: Agendar uma reunião com o cliente | M5: 46216 | N5: Proposta remetida para validação | O5: =IF(C5="","",MAX(0,TODAY()-C5)) -> 49 | P5: =IF(OR(G5="",J5=""),"",G5*J5) -> 7767504 | Q5: A | R5: Média | S5: Aberto | T5: =IF(K5="","",IFERROR(VLOOKUP(K5,Listas!$G$2:$J$8,4,FALSE),0)) -> 7500000 | U5: =IFERROR(H5/T5,0) -> 0
A6: Semana Anterior | B6: 5 | C6: 46211 | D6: ALIANÇA SEGUROS | E6: Fornecimento de Flyers dipticos | F6: Proposta enviada | G6: 3328800 | H6: 0 | I6: 0 | J6: 0.4 | K6: Luísa Baltazar | L6: Considerar a possibilidade de apresentar um desconto | M6: 46216 | N6: Proposta remetida para validação | O6: =IF(C6="","",MAX(0,TODAY()-C6)) -> 48 | P6: =IF(OR(G6="",J6=""),"",G6*J6) -> 1331520 | Q6: A | R6: Normal | S6: Aberto | T6: =IF(K6="","",IFERROR(VLOOKUP(K6,Listas!$G$2:$J$8,4,FALSE),0)) -> 7500000 | U6: =IFERROR(H6/T6,0) -> 0
A7: Semana Anterior | B7: 6 | C7: 46212 | D7: COSCAL | E7: Fornecimento de flyers Tripticos | F7: Produção / Entrega | G7: 259350 | H7: 259350 | I7: 0 | J7: 1 | K7: Luísa Baltazar | L7: Conseguir o contacto do cliente final | M7: 46216 | N7: Material produzido e entregue | O7: =IF(C7="","",MAX(0,TODAY()-C7)) -> 47 | P7: =IF(OR(G7="",J7=""),"",G7*J7) -> 259350 | Q7: A | R7: Alta | S7: Aberto | T7: =IF(K7="","",IFERROR(VLOOKUP(K7,Listas!$G$2:$J$8,4,FALSE),0)) -> 7500000 | U7: =IFERROR(H7/T7,0) -> 0.03458
A8: Semana Anterior | B8: 7 | C8: 46189 | D8: ENDIAMA | E8: Fornecimento de materiais para outubro rosa | F8: Proposta em negociação | G8: 6958560 | H8: 0 | I8: 0 | J8: 0.8 | K8: Luísa Baltazar | L8: negociar a modadlidade de pagamento | M8: 46216 | N8: Falta o envio da PO, para credibilizar a adjudicação do processo | O8: =IF(C8="","",MAX(0,TODAY()-C8)) -> 70 | P8: =IF(OR(G8="",J8=""),"",G8*J8) -> 5566848 | Q8: C | R8: Alta | S8: Aberto | T8: =IF(K8="","",IFERROR(VLOOKUP(K8,Listas!$G$2:$J$8,4,FALSE),0)) -> 7500000 | U8: =IFERROR(H8/T8,0) -> 0
A9: Semana Anterior | B9: 8 | C9: 46198 | D9: PAY4ALL | E9: Fornecimento de Brindes para a filda | F9: Proposta aprovada | G9: 2106150 | H9: 2106150 | I9: 0 | J9: 1 | K9: Amélia Cassinda | L9: Acompanharo processo de produção externa e interna, para cumprir com o prazo | M9: 46216 | N9: Avaliação e criação de artes finais para produção | O9: =IF(C9="","",MAX(0,TODAY()-C9)) -> 61 | P9: =IF(OR(G9="",J9=""),"",G9*J9) -> 2106150 | Q9: C | R9: Alta | S9: Fechado ganho | T9: =IF(K9="","",IFERROR(VLOOKUP(K9,Listas!$G$2:$J$8,4,FALSE),0)) -> 6250000 | U9: =IFERROR(H9/T9,0) -> 0.336984
A10: Semana Anterior | B10: 9 | C10: 46209 | D10: XPRINT | E10: Fornecimento de Brindes e Têxtil | F10: Proposta enviada | G10: 2350680 | H10: 0 | I10: 0 | J10: 0.4 | K10: Amélia Cassinda | L10: Considerar a possibilidade de apresentar um desconto | M10: 46216 | N10: Proposta remetida para avaliação | O10: =IF(C10="","",MAX(0,TODAY()-C10)) -> 50 | P10: =IF(OR(G10="",J10=""),"",G10*J10) -> 940272 | Q10: B | R10: Normal | S10: Aberto | T10: =IF(K10="","",IFERROR(VLOOKUP(K10,Listas!$G$2:$J$8,4,FALSE),0)) -> 6250000 | U10: =IFERROR(H10/T10,0) -> 0
A11: Semana Anterior | B11: 10 | C11: 46213 | D11: DUBAI INVESTIMETS | E11: Forneciemnto de Brindes | F11: Proposta enviada | G11: 6156000 | H11: 0 | I11: 0 | J11: 0.5 | K11: Amélia Cassinda | L11: Apresentar amostras Físicas e acompanhar o processo | M11: 46216 | N11: Proposta remetida para avaliação | O11: =IF(C11="","",MAX(0,TODAY()-C11)) -> 46 | P11: =IF(OR(G11="",J11=""),"",G11*J11) -> 3078000 | Q11: C | R11: Média | S11: Aberto | T11: =IF(K11="","",IFERROR(VLOOKUP(K11,Listas!$G$2:$J$8,4,FALSE),0)) -> 6250000 | U11: =IFERROR(H11/T11,0) -> 0
A12: Semana Anterior | B12: 11 | C12: 46211 | D12: DUBAI INVESTIMETS | E12: Fornecimento de Flyrs | F12: Proposta enviada | G12: 3249000 | H12: 0 | I12: 0 | J12: 0.4 | K12: Amélia Cassinda | L12: Apresentar amostras Físicas e acompanhar o processo | M12: 46216 | N12: Proposta remetida para avaliação | O12: =IF(C12="","",MAX(0,TODAY()-C12)) -> 48 | P12: =IF(OR(G12="",J12=""),"",G12*J12) -> 1299600 | Q12: C | R12: Normal | S12: Aberto | T12: =IF(K12="","",IFERROR(VLOOKUP(K12,Listas!$G$2:$J$8,4,FALSE),0)) -> 6250000 | U12: =IFERROR(H12/T12,0) -> 0
A13: Semana Anterior | B13: 12 | C13: 46209 | D13: BCGA | E13: Fornecimento de Lenços e gravatas | F13: Perdida | G13: 9095000 | H13: 0 | I13: 9095000 | J13: 0 | K13: Amélia Cassinda | L13: Apresentação de disponibilidade para futurod projectos | M13: 46216 | N13: Proposta rejeitada, por causa do tempo de produção e pelo fornecedor não ter o mesmo tecido | O13: =IF(C13="","",MAX(0,TODAY()-C13)) -> 50 | P13: =IF(OR(G13="",J13=""),"",G13*J13) -> 0 | Q13: C | R13: Média | S13: Fechado perdido | T13: =IF(K13="","",IFERROR(VLOOKUP(K13,Listas!$G$2:$J$8,4,FALSE),0)) -> 6250000 | U13: =IFERROR(H13/T13,0) -> 0
... A32: Semana Anterior | B32: 31 | C32: 46213 | D32: BAXTTER | E32: Fornecimento de brindes e flyres | F32: Proposta enviada | G32: 1657560 | H32: 0 | I32: 0 | J32: 0.4 | K32: Fernando Leite | L32: Solicitar o ponto de situação da proposta | M32: 46216 | N32: Proposta remetida para avaliação | O32: =IF(C32="","",MAX(0,TODAY()-C32)) -> 46 | P32: =IF(OR(G32="",J32=""),"",G32*J32) -> 663024 | Q32: C | R32: Normal | S32: Aberto | T32: =IF(K32="","",IFERROR(VLOOKUP(K32,Listas!$G$2:$J$8,4,FALSE),0)) -> 2500000 | U32: =IFERROR(H32/T32,0) -> 0
O33: =IF(C33="","",MAX(0,TODAY()-C33)) | P33: =IF(OR(G33="",J33=""),"",G33*J33) | T33: =IF(K33="","",IFERROR(VLOOKUP(K33,Listas!$G$2:$J$8,4,FALSE),0)) | U33: =IFERROR(H33/T33,0) -> 0
A34: Semana Finda | B34: 1 | C34: 46216 | D34: UNITEL | E34: Canecas de Porcelana e Garrafas Térmica | F34: Proposta enviada | G34: 96124800 | H34: 0 | I34: 0 | J34: 0.4 | K34: Luísa Baltazar | L34: Incentivar o cliente para o envio da contraproposta. | M34: 46223 | N34: O processo de análise das propostas está em curso | O34: =IF(C34="","",MAX(0,TODAY()-C34)) -> 43 | P34: =IF(OR(G34="",J34=""),"",G34*J34) -> 38449920 | Q34: A | R34: Alta | S34: Aberto | T34: =IF(K34="","",IFERROR(VLOOKUP(K34,Listas!$G$2:$J$8,4,FALSE),0)) -> 7500000 | U34: =IFERROR(H34/T34,0) -> 0
A35: Semana Finda | B35: 2 | C35: 46218 | D35: FINSTAR/ZAP | E35: Sacos TNT Personalizados | F35: Proposta aprovada | G35: 1687200 | H35: 1687200 | I35: 0 | J35: 1 | K35: Luísa Baltazar | L35: Pressionar a adjudicação da proposta das T-Shirts | M35: 46223 | N35: Já entregamos 300 unidades. A entrega será concluída no dia 20 de Julho | O35: =IF(C35="","",MAX(0,TODAY()-C35)) -> 41 | P35: =IF(OR(G35="",J35=""),"",G35*J35) -> 1687200 | Q35: A | R35: Média | S35: Fechado ganho | T35: =IF(K35="","",IFERROR(VLOOKUP(K35,Listas!$G$2:$J$8,4,FALSE),0)) -> 7500000 | U35: =IFERROR(H35/T35,0) -> 0.22496
A36: Semana Finda | B36: 3 | C36: 46217 | D36: FINSTAR/ZAP | E36: T-Shirts para Lojistas | F36: Proposta em negociação | G36: 21161250 | H36: 0 | I36: 0 | J36: 0.6 | K36: Luísa Baltazar | L36: Solicitar o ponto de situação da PO | M36: 46223 | N36: Aguardamos a formalização da adjudicação | O36: =IF(C36="","",MAX(0,TODAY()-C36)) -> 42 | P36: =IF(OR(G36="",J36=""),"",G36*J36) -> 12696750 | Q36: A | R36: Alta | S36: Aberto | T36: =IF(K36="","",IFERROR(VLOOKUP(K36,Listas!$G$2:$J$8,4,FALSE),0)) -> 7500000 | U36: =IFERROR(H36/T36,0) -> 0
A37: Semana Finda | B37: 4 | C37: 46218 | D37: CARPINANGOLA/CASAIS | E37: Bloco de Notas e Canetas | F37: Proposta aprovada | G37: 2017800 | H37: 2017800 | I37: 0 | J37: 1 | K37: Luísa Baltazar | L37: Alinhamento com a cliente para obter mais trabalhos | M37: 46223 | N37: O processo de produção está em curso, faremos a entrega no dia 20 de Julho | O37: =IF(C37="","",MAX(0,TODAY()-C37)) -> 41 | P37: =IF(OR(G37="",J37=""),"",G37*J37) -> 2017800 | Q37: B | R37: Alta | S37: Fechado ganho | T37: =IF(K37="","",IFERROR(VLOOKUP(K37,Listas!$G$2:$J$8,4,FALSE),0)) -> 7500000 | U37: =IFERROR(H37/T37,0) -> 0.26904
A38: Semana Finda | B38: 5 | C38: 46220 | D38: CEGID/PRIMAVERA | E38: Impressão de Flyers | F38: Proposta aprovada | G38: 445700 | H38: 445700 | I38: 0 | J38: 1 | K38: Luísa Baltazar | L38: Cumprimento do prazo de entrega | M38: 46223 | N38: O processo de produção está em curso, faremos a entrega no dia 20 de Julho | O38: =IF(C38="","",MAX(0,TODAY()-C38)) -> 39 | P38: =IF(OR(G38="",J38=""),"",G38*J38) -> 445700 | Q38: B | R38: Alta | S38: Fechado ganho | T38: =IF(K38="","",IFERROR(VLOOKUP(K38,Listas!$G$2:$J$8,4,FALSE),0)) -> 7500000 | U38: =IFERROR(H38/T38,0) -> 0.059426667
A39: Semana Finda | B39: 6 | C39: 46220 | D39: FINSTAR/ZAP | E39: T-Shirts para Filda | F39: Proposta enviada | G39: 1966500 | H39: 0 | I39: 0 | J39: 0.5 | K39: Luísa Baltazar | L39: Persuadir a aprovação usando o prazo de entrega do estratégia | M39: 46223 | N39: As propostas ainda estão a ser analisadas | O39: =IF(C39="","",MAX(0,TODAY()-C39)) -> 39 | P39: =IF(OR(G39="",J39=""),"",G39*J39) -> 983250 | Q39: A | R39: Normal | S39: Aberto | T39: =IF(K39="","",IFERROR(VLOOKUP(K39,Listas!$G$2:$J$8,4,FALSE),0)) -> 7500000 | U39: =IFERROR(H39/T39,0) -> 0
A40: Semana Finda | B40: 7 | C40: 46219 | D40: SIAC | E40: Totens em Betão | F40: Proposta enviada | G40: 29641900 | H40: 0 | I40: 0 | J40: 0.4 | K40: Luísa Baltazar | L40: Solicitar uma reunião com este cliente | M40: 46223 | N40: A nossa proposta foi submetida para avaliação | O40: =IF(C40="","",MAX(0,TODAY()-C40)) -> 40 | P40: =IF(OR(G40="",J40=""),"",G40*J40) -> 11856760 | Q40: C | R40: Normal | S40: Aberto | T40: =IF(K40="","",IFERROR(VLOOKUP(K40,Listas!$G$2:$J$8,4,FALSE),0)) -> 7500000 | U40: =IFERROR(H40/T40,0) -> 0
A41: Semana Finda | B41: 8 | C41: 46182 | D41: SBM OFFSHORE | E41: Impressão de Autocolante | F41: Proposta aprovada | G41: 339150 | H41: 339150 | I41: 0 | J41: 1 | K41: Amélia Cassinda | L41: Entrega do material ao cliente | M41: 46223 | N41: O material está pronto para ser entregue | O41: =IF(C41="","",MAX(0,TODAY()-C41)) -> 77 | P41: =IF(OR(G41="",J41=""),"",G41*J41) -> 339150 | Q41: A | R41: Normal | S41: Fechado ganho | T41: =IF(K41="","",IFERROR(VLOOKUP(K41,Listas!$G$2:$J$8,4,FALSE),0)) -> 6250000 | U41: =IFERROR(H41/T41,0) -> 0.054264
A42: Semana Finda | B42: 9 | C42: 46216 | D42: BCGA | E42: Fornecimento de Sacolas | F42: Proposta aprovada | G42: 3135000 | H42: 3135000 | I42: 0 | J42: 1 | K42: Amélia Cassinda | L42: Levantar o material do cliente no fornecedor | M42: 46223 | N42: Material em produção no fornecedor | O42: =IF(C42="","",MAX(0,TODAY()-C42)) -> 43 | P42: =IF(OR(G42="",J42=""),"",G42*J42) -> 3135000 | Q42: A | R42: Alta | S42: Fechado ganho | T42: =IF(K42="","",IFERROR(VLOOKUP(K42,Listas!$G$2:$J$8,4,FALSE),0)) -> 6250000 | U42: =IFERROR(H42/T42,0) -> 0.5016
A43: Semana Finda | B43: 10 | C43: 46216 | D43: TREVOTECH | E43: Fornecimento de Polos | F43: Proposta aprovada | G43: 889200 | H43: 889200 | I43: 0 | J43: 1 | K43: Amélia Cassinda | L43: Solicitar feedback do material entregue | M43: 46223 | N43: Material produzido e entregue | O43: =IF(C43="","",MAX(0,TODAY()-C43)) -> 43 | P43: =IF(OR(G43="",J43=""),"",G43*J43) -> 889200 | Q43: C | R43: Normal | S43: Fechado ganho | T43: =IF(K43="","",IFERROR(VLOOKUP(K43,Listas!$G$2:$J$8,4,FALSE),0)) -> 6250000 | U43: =IFERROR(H43/T43,0) -> 0.142272
A44: Semana Finda | B44: 11 | C44: 46220 | D44: ANGOLACA | E44: Fornecimento de Materiais Diversos | F44: Proposta enviada | G44: 14248432 | H44: 0 | I44: 0 | J44: 0.5 | K44: Amélia Cassinda | L44: Contactar a cliente para agendar uma reunião | M44: 46223 | N44: Proposta remetida para avaliação | O44: =IF(C44="","",MAX(0,TODAY()-C44)) -> 39 | P44: =IF(OR(G44="",J44=""),"",G44*J44) -> 7124216.2 | Q44: C | R44: Média | S44: Aberto | T44: =IF(K44="","",IFERROR(VLOOKUP(K44,Listas!$G$2:$J$8,4,FALSE),0)) -> 6250000 | U44: =IFERROR(H44/T44,0) -> 0
A45: Semana Finda | B45: 12 | C45: 46217 | D45: DUBAI INVESTIMETS | E45: Fornecimento de Garrafas Térmicas | F45: Proposta enviada | G45: 29724360 | H45: 0 | I45: 0 | J45: 0.4 | K45: Amélia Cassinda | L45: Avaliar a possibilidade de dar um desconto | M45: 46223 | N45: Proposta remetida para avaliação | O45: =IF(C45="","",MAX(0,TODAY()-C45)) -> 42 | P45: =IF(OR(G45="",J45=""),"",G45*J45) -> 11889744 | Q45: C | R45: Média | S45: Aberto | T45: =IF(K45="","",IFERROR(VLOOKUP(K45,Listas!$G$2:$J$8,4,FALSE),0)) -> 6250000 | U45: =IFERROR(H45/T45,0) -> 0
... A56: Semana Finda | B56: 23 | C56: 46220 | D56: DP WORLD | E56: Placas em PVC com Vinil | F56: Proposta em negociação | G56: 1962624 | H56: 0 | I56: 0 | J56: 0.5 | K56: David Guedes | L56: Persuadir a aprovação | M56: 46223 | N56: Já oferecemos um desconto na proposta | O56: =IF(C56="","",MAX(0,TODAY()-C56)) -> 39 | P56: =IF(OR(G56="",J56=""),"",G56*J56) -> 981312 | Q56: B | R56: Alta | S56: Aberto | T56: =IF(K56="","",IFERROR(VLOOKUP(K56,Listas!$G$2:$J$8,4,FALSE),0)) -> 3750000 | U56: =IFERROR(H56/T56,0) -> 0
A57: Semana Finda | B57: 24 | C57: 46219 | D57: DP WORLD | E57: Quadros em Acrílico para Documentos | F57: Proposta enviada | G57: 1590300 | H57: 0 | I57: 0 | J57: 0.5 | K57: David Guedes | L57: Considerar a possibilidade de apresentar um desconto | M57: 46223 | N57: A nossa proposta está a ser analisada pelo cliente | O57: =IF(C57="","",MAX(0,TODAY()-C57)) -> 40 | P57: =IF(OR(G57="",J57=""),"",G57*J57) -> 795150 | R57: Alta | S57: Aberto | T57: =IF(K57="","",IFERROR(VLOOKUP(K57,Listas!$G$2:$J$8,4,FALSE),0)) -> 3750000 | U57: =IFERROR(H57/T57,0) -> 0
A58: Semana Finda | B58: 25 | C58: 46218 | D58: DP WORLD | E58: Fornecimento de Materiais Diversos | F58: Proposta enviada | G58: 1133502 | H58: 0 | I58: 0 | J58: 0.5 | K58: David Guedes | L58: Entrar em contacto com o cliente e persuadir o fecho | M58: 46223 | N58: Enviamos a proposta e aguardamos feedback do cliente | O58: =IF(C58="","",MAX(0,TODAY()-C58)) -> 41 | P58: =IF(OR(G58="",J58=""),"",G58*J58) -> 566751 | Q58: B | R58: Alta | S58: Aberto | T58: =IF(K58="","",IFERROR(VLOOKUP(K58,Listas!$G$2:$J$8,4,FALSE),0)) -> 3750000 | U58: =IFERROR(H58/T58,0) -> 0
A59: Semana Finda | B59: 26 | C59: 46217 | D59: AUTOMATRIZ | E59: Fornecimento e Aplicação de Lona | F59: Proposta em negociação | G59: 405840 | H59: 0 | I59: 0 | J59: 0.5 | K59: David Guedes | L59: Produção da amostra solicitada | M59: 46223 | N59: A princípio rejeitamos a produção da amostra, mas vamos analisar melhor | O59: =IF(C59="","",MAX(0,TODAY()-C59)) -> 42 | P59: =IF(OR(G59="",J59=""),"",G59*J59) -> 202920 | Q59: B | R59: Normal | S59: Aberto | T59: =IF(K59="","",IFERROR(VLOOKUP(K59,Listas!$G$2:$J$8,4,FALSE),0)) -> 3750000 | U59: =IFERROR(H59/T59,0) -> 0
A60: Semana Finda | B60: 27 | C60: 46220 | D60: POLITEJO | E60: Impressão de Vinil Autocolante | F60: Proposta aprovada | G60: 49590 | H60: 49590 | I60: 0 | J60: 1 | K60: Ilídio Pedro | L60: Manter o contacto com o cliente para gerar novos negócios | M60: 46223 | N60: O material já foi produzido | O60: =IF(C60="","",MAX(0,TODAY()-C60)) -> 39 | P60: =IF(OR(G60="",J60=""),"",G60*J60) -> 49590 | Q60: C | R60: Média | S60: Fechado ganho | T60: =IF(K60="","",IFERROR(VLOOKUP(K60,Listas!$G$2:$J$8,4,FALSE),0)) -> 2500000 | U60: =IFERROR(H60/T60,0) -> 0.019836
A61: Semana Finda | B61: 28 | C61: 46217 | D61: RÁDIO NACIONAL DE ANGOLA | E61: Brindes para Filda | F61: Perdida | G61: 3243300 | H61: 0 | I61: 3243300 | J61: 0 | K61: Ilídio Pedro | L61: Negociar a parceria com este cliente | M61: 46223 | N61: A parceria proposta pelo cliente era apenas benéfica para eles | O61: =IF(C61="","",MAX(0,TODAY()-C61)) -> 42 | P61: =IF(OR(G61="",J61=""),"",G61*J61) -> 0 | Q61: C | R61: Baixa | S61: Fechado perdido | T61: =IF(K61="","",IFERROR(VLOOKUP(K61,Listas!$G$2:$J$8,4,FALSE),0)) -> 2500000 | U61: =IFERROR(H61/T61,0) -> 0
A62: Semana Finda | B62: 29 | C62: 46217 | D62: SONANGOL PESQUISA E PRODUÇÃO | E62: Brindes para Filda | F62: Proposta aprovada | G62: 7927560 | H62: 7927560 | I62: 0 | J62: 1 | K62: Ilídio Pedro | L62: Cumprimento do prazo de entrega | M62: 46223 | N62: O material está em produção | O62: =IF(C62="","",MAX(0,TODAY()-C62)) -> 42 | P62: =IF(OR(G62="",J62=""),"",G62*J62) -> 7927560 | Q62: C | R62: Alta | S62: Fechado ganho | T62: =IF(K62="","",IFERROR(VLOOKUP(K62,Listas!$G$2:$J$8,4,FALSE),0)) -> 2500000 | U62: =IFERROR(H62/T62,0) -> 3.171024
A63: Semana Finda | B63: 30 | C63: 46211 | D63: 5 LINHAS TELECOMUNICAÇÕES | E63: Brindes, Têxteis e Papelaria | F63: Perdida | G63: 8468775 | H63: 0 | I63: =G63 -> 8468775 | J63: 0 | K63: Fernando Leite | L63: Apresentar outras soluções ao cliente | M63: 46223 | N63: O cliente optou por avançar com outro fornecedor | O63: =IF(C63="","",MAX(0,TODAY()-C63)) -> 48 | P63: =IF(OR(G63="",J63=""),"",G63*J63) -> 0 | Q63: C | R63: Normal | S63: Fechado perdido | T63: =IF(K63="","",IFERROR(VLOOKUP(K63,Listas!$G$2:$J$8,4,FALSE),0)) -> 2500000 | U63: =IFERROR(H63/T63,0) -> 0
A64: Semana Finda | B64: 31 | C64: 46216 | D64: GRUPO CASTEL | E64: Impressão de Código de Conduta | F64: Proposta enviada | G64: 6002100 | H64: 0 | I64: 0 | J64: 0.4 | K64: Fernando Leite | L64: Contactar o cliente para confirmar se recebeu a proposta | M64: 46223 | N64: Enviamos a proposta mas o cliente não deu feedback | O64: =IF(C64="","",MAX(0,TODAY()-C64)) -> 43 | P64: =IF(OR(G64="",J64=""),"",G64*J64) -> 2400840 | Q64: C | R64: Alta | S64: Aberto | T64: =IF(K64="","",IFERROR(VLOOKUP(K64,Listas!$G$2:$J$8,4,FALSE),0)) -> 2500000 | U64: =IFERROR(H64/T64,0) -> 0
A65: Semana Finda | B65: 32 | C65: 46218 | D65: BAXTTER | E65: Impressão de Flyers | F65: Proposta aprovada | G65: 444600 | H65: 444600 | I65: 0 | J65: 1 | K65: Fernando Leite | L65: Levantamento do material no fornecedor entrega ao cliente | M65: 46223 | N65: O material está pronto para ser entregue | O65: =IF(C65="","",MAX(0,TODAY()-C65)) -> 41 | P65: =IF(OR(G65="",J65=""),"",G65*J65) -> 444600 | Q65: C | R65: Normal | S65: Fechado ganho | T65: =IF(K65="","",IFERROR(VLOOKUP(K65,Listas!$G$2:$J$8,4,FALSE),0)) -> 2500000 | U65: =IFERROR(H65/T65,0) -> 0.17784
O66: =IF(C66="","",MAX(0,TODAY()-C66)) | P66: =IF(OR(G66="",J66=""),"",G66*J66) | T66: =IF(K66="","",IFERROR(VLOOKUP(K66,Listas!$G$2:$J$8,4,FALSE),0)) | U66: =IFERROR(H66/T66,0) -> 0
O67: =IF(C67="","",MAX(0,TODAY()-C67)) | P67: =IF(OR(G67="",J67=""),"",G67*J67) | T67: =IF(K67="","",IFERROR(VLOOKUP(K67,Listas!$G$2:$J$8,4,FALSE),0)) | U67: =IFERROR(H67/T67,0) -> 0
O68: =IF(C68="","",MAX(0,TODAY()-C68)) | P68: =IF(OR(G68="",J68=""),"",G68*J68) | T68: =IF(K68="","",IFERROR(VLOOKUP(K68,Listas!$G$2:$J$8,4,FALSE),0)) | U68: =IFERROR(H68/T68,0) -> 0
...

Sheet Metas_Performance
A1: METAS E PERFORMANCE POR COMERCIAL – SEMANA FINDA
A4: Comercial | B4: Função | C4: Meta semanal | D4: Propostas | E4: Valor total | F4: Aprovado | G4: % Meta | H4: Pipeline aberto | I4: Forecast | J4: Leitura
A5: Amélia Cassinda | B5: Sénior | C5: 6250000 | D5: =COUNTIFS(Base_Duas_Semanas!$A$4:$A$464,"Semana Finda",Base_Duas_Semanas!$K$4:$K$464,A5) -> 6 | E5: =SUMIFS(Base_Duas_Semanas!$G$4:$G$464,Base_Duas_Semanas!$A$4:$A$464,"Semana Finda",Base_Duas_Semanas!$K$4:$K$464,A5) -> 51919142 | F5: =SUMIFS(Base_Duas_Semanas!$H$4:$H$464,Base_Duas_Semanas!$A$4:$A$464,"Semana Finda",Base_Duas_Semanas!$K$4:$K$464,A5) -> 4363350 | G5: =IFERROR(F5/C5,0) -> 0.698136 | H5: =SUMIFS(Base_Duas_Semanas!$G$4:$G$464,Base_Duas_Semanas!$A$4:$A$464,"Semana Finda",Base_Duas_Semanas!$K$4:$K$464,A5,Base_Duas_Semanas!$S$4:$S$464,"Aberto") -> 47555792 | I5: =SUMIFS(Base_Duas_Semanas!$P$4:$P$464,Base_Duas_Semanas!$A$4:$A$464,"Semana Finda",Base_Duas_Semanas!$K$4:$K$464,A5) -> 24810510 | J5: =IF(D5=0,"Sem actividade",IF(G5>=1,"Meta atingida",IF(G5>=0.6,"Acelerar fecho","Intervenção comercial necessária"))) -> Acelerar fecho
A6: David Guedes | B6: Comercial | C6: 3750000 | D6: =COUNTIFS(Base_Duas_Semanas!$A$4:$A$464,"Semana Finda",Base_Duas_Semanas!$K$4:$K$464,A6) -> 5 | E6: =SUMIFS(Base_Duas_Semanas!$G$4:$G$464,Base_Duas_Semanas!$A$4:$A$464,"Semana Finda",Base_Duas_Semanas!$K$4:$K$464,A6) -> 8261979 | F6: =SUMIFS(Base_Duas_Semanas!$H$4:$H$464,Base_Duas_Semanas!$A$4:$A$464,"Semana Finda",Base_Duas_Semanas!$K$4:$K$464,A6) -> 0 | G6: =IFERROR(F6/C6,0) -> 0 | H6: =SUMIFS(Base_Duas_Semanas!$G$4:$G$464,Base_Duas_Semanas!$A$4:$A$464,"Semana Finda",Base_Duas_Semanas!$K$4:$K$464,A6,Base_Duas_Semanas!$S$4:$S$464,"Aberto") -> 8261979 | I6: =SUMIFS(Base_Duas_Semanas!$P$4:$P$464,Base_Duas_Semanas!$A$4:$A$464,"Semana Finda",Base_Duas_Semanas!$K$4:$K$464,A6) -> 3814018.2 | J6: =IF(D6=0,"Sem actividade",IF(G6>=1,"Meta atingida",IF(G6>=0.6,"Acelerar fecho","Intervenção comercial necessária"))) -> Intervenção comercial necessária
A7: Fernando Leite | B7: Comercial | C7: 2500000 | D7: =COUNTIFS(Base_Duas_Semanas!$A$4:$A$464,"Semana Finda",Base_Duas_Semanas!$K$4:$K$464,A7) -> 3 | E7: =SUMIFS(Base_Duas_Semanas!$G$4:$G$464,Base_Duas_Semanas!$A$4:$A$464,"Semana Finda",Base_Duas_Semanas!$K$4:$K$464,A7) -> 14915475 | F7: =SUMIFS(Base_Duas_Semanas!$H$4:$H$464,Base_Duas_Semanas!$A$4:$A$464,"Semana Finda",Base_Duas_Semanas!$K$4:$K$464,A7) -> 444600 | G7: =IFERROR(F7/C7,0) -> 0.17784 | H7: =SUMIFS(Base_Duas_Semanas!$G$4:$G$464,Base_Duas_Semanas!$A$4:$A$464,"Semana Finda",Base_Duas_Semanas!$K$4:$K$464,A7,Base_Duas_Semanas!$S$4:$S$464,"Aberto") -> 6002100 | I7: =SUMIFS(Base_Duas_Semanas!$P$4:$P$464,Base_Duas_Semanas!$A$4:$A$464,"Semana Finda",Base_Duas_Semanas!$K$4:$K$464,A7) -> 2845440 | J7: =IF(D7=0,"Sem actividade",IF(G7>=1,"Meta atingida",IF(G7>=0.6,"Acelerar fecho","Intervenção comercial necessária"))) -> Intervenção comercial necessária
A8: Ilídio Pedro | B8: Comercial | C8: 2500000 | D8: =COUNTIFS(Base_Duas_Semanas!$A$4:$A$464,"Semana Finda",Base_Duas_Semanas!$K$4:$K$464,A8) -> 3 | E8: =SUMIFS(Base_Duas_Semanas!$G$4:$G$464,Base_Duas_Semanas!$A$4:$A$464,"Semana Finda",Base_Duas_Semanas!$K$4:$K$464,A8) -> 11220450 | F8: =SUMIFS(Base_Duas_Semanas!$H$4:$H$464,Base_Duas_Semanas!$A$4:$A$464,"Semana Finda",Base_Duas_Semanas!$K$4:$K$464,A8) -> 7977150 | G8: =IFERROR(F8/C8,0) -> 3.19086 | H8: =SUMIFS(Base_Duas_Semanas!$G$4:$G$464,Base_Duas_Semanas!$A$4:$A$464,"Semana Finda",Base_Duas_Semanas!$K$4:$K$464,A8,Base_Duas_Semanas!$S$4:$S$464,"Aberto") -> 0 | I8: =SUMIFS(Base_Duas_Semanas!$P$4:$P$464,Base_Duas_Semanas!$A$4:$A$464,"Semana Finda",Base_Duas_Semanas!$K$4:$K$464,A8) -> 7977150 | J8: =IF(D8=0,"Sem actividade",IF(G8>=1,"Meta atingida",IF(G8>=0.6,"Acelerar fecho","Intervenção comercial necessária"))) -> Meta atingida
A9: José Neto | B9: Sénior | C9: 5000000 | D9: =COUNTIFS(Base_Duas_Semanas!$A$4:$A$464,"Semana Finda",Base_Duas_Semanas!$K$4:$K$464,A9) -> 3 | E9: =SUMIFS(Base_Duas_Semanas!$G$4:$G$464,Base_Duas_Semanas!$A$4:$A$464,"Semana Finda",Base_Duas_Semanas!$K$4:$K$464,A9) -> 4794498 | F9: =SUMIFS(Base_Duas_Semanas!$H$4:$H$464,Base_Duas_Semanas!$A$4:$A$464,"Semana Finda",Base_Duas_Semanas!$K$4:$K$464,A9) -> 0 | G9: =IFERROR(F9/C9,0) -> 0 | H9: =SUMIFS(Base_Duas_Semanas!$G$4:$G$464,Base_Duas_Semanas!$A$4:$A$464,"Semana Finda",Base_Duas_Semanas!$K$4:$K$464,A9,Base_Duas_Semanas!$S$4:$S$464,"Aberto") -> 4794498 | I9: =SUMIFS(Base_Duas_Semanas!$P$4:$P$464,Base_Duas_Semanas!$A$4:$A$464,"Semana Finda",Base_Duas_Semanas!$K$4:$K$464,A9) -> 1917799.2 | J9: =IF(D9=0,"Sem actividade",IF(G9>=1,"Meta atingida",IF(G9>=0.6,"Acelerar fecho","Intervenção comercial necessária"))) -> Intervenção comercial necessária
A10: Luísa Baltazar | B10: Sénior EDGE | C10: 7500000 | D10: =COUNTIFS(Base_Duas_Semanas!$A$4:$A$464,"Semana Finda",Base_Duas_Semanas!$K$4:$K$464,A10) -> 7 | E10: =SUMIFS(Base_Duas_Semanas!$G$4:$G$464,Base_Duas_Semanas!$A$4:$A$464,"Semana Finda",Base_Duas_Semanas!$K$4:$K$464,A10) -> 153045150 | F10: =SUMIFS(Base_Duas_Semanas!$H$4:$H$464,Base_Duas_Semanas!$A$4:$A$464,"Semana Finda",Base_Duas_Semanas!$K$4:$K$464,A10) -> 4150700 | G10: =IFERROR(F10/C10,0) -> 0.55342667 | H10: =SUMIFS(Base_Duas_Semanas!$G$4:$G$464,Base_Duas_Semanas!$A$4:$A$464,"Semana Finda",Base_Duas_Semanas!$K$4:$K$464,A10,Base_Duas_Semanas!$S$4:$S$464,"Aberto") -> 148894450 | I10: =SUMIFS(Base_Duas_Semanas!$P$4:$P$464,Base_Duas_Semanas!$A$4:$A$464,"Semana Finda",Base_Duas_Semanas!$K$4:$K$464,A10) -> 68137380 | J10: =IF(D10=0,"Sem actividade",IF(G10>=1,"Meta atingida",IF(G10>=0.6,"Acelerar fecho","Intervenção comercial necessária"))) -> Intervenção comercial necessária
A11: Marta de Oliveira | B11: Sénior | C11: 6250000 | D11: =COUNTIFS(Base_Duas_Semanas!$A$4:$A$464,"Semana Finda",Base_Duas_Semanas!$K$4:$K$464,A11) -> 5 | E11: =SUMIFS(Base_Duas_Semanas!$G$4:$G$464,Base_Duas_Semanas!$A$4:$A$464,"Semana Finda",Base_Duas_Semanas!$K$4:$K$464,A11) -> 19293737 | F11: =SUMIFS(Base_Duas_Semanas!$H$4:$H$464,Base_Duas_Semanas!$A$4:$A$464,"Semana Finda",Base_Duas_Semanas!$K$4:$K$464,A11) -> 9826550 | G11: =IFERROR(F11/C11,0) -> 1.572248 | H11: =SUMIFS(Base_Duas_Semanas!$G$4:$G$464,Base_Duas_Semanas!$A$4:$A$464,"Semana Finda",Base_Duas_Semanas!$K$4:$K$464,A11,Base_Duas_Semanas!$S$4:$S$464,"Aberto") -> 9467187 | I11: =SUMIFS(Base_Duas_Semanas!$P$4:$P$464,Base_Duas_Semanas!$A$4:$A$464,"Semana Finda",Base_Duas_Semanas!$K$4:$K$464,A11) -> 13613425 | J11: =IF(D11=0,"Sem actividade",IF(G11>=1,"Meta atingida",IF(G11>=0.6,"Acelerar fecho","Intervenção comercial necessária"))) -> Meta atingida

Sheet CRM_Proxima_Semana
A1: RECOMENDAÇÕES DE CRM – PRÓXIMA SEMANA E ACOMPANHAMENTO
A4: Cliente | B4: Comercial | C4: Estado | D4: Valor | E4: Prioridade | F4: Dias em aberto | G4: Recomendação automática | H4: Prazo | I4: Resultado esperado | J4: Acompanhamento | K4: Observação final
A5: UNITEL | B5: Luísa Baltazar | C5: Proposta enviada | D5: 96124800 | E5: Alta | F5: 6 | G5: =IF(OR(E5="Alta",D5>=10000000),"Contacto directo ao decisor e reunião de fecho",IF(F5>15,"Reactivar processo e solicitar decisão formal","Executar próxima acção e actualizar CRM")) -> Contacto directo ao decisor e reunião de fecho | H5: =IF(OR(E5="Alta",D5>=10000000),"48 horas","Até 5 dias úteis") -> 48 horas | I5: =IF(C5="Proposta em negociação","Obter PO, adjudicação ou data formal de decisão","Obter feedback e evolução do estado") -> Obter feedback e evolução do estado | J5: Pendente
A6: FINSTAR/ZAP | B6: Luísa Baltazar | C6: Proposta aprovada | D6: 1687200 | E6: Média | F6: 4 | G6: =IF(OR(E6="Alta",D6>=10000000),"Contacto directo ao decisor e reunião de fecho",IF(F6>15,"Reactivar processo e solicitar decisão formal","Executar próxima acção e actualizar CRM")) -> Executar próxima acção e actualizar CRM | H6: =IF(OR(E6="Alta",D6>=10000000),"48 horas","Até 5 dias úteis") -> Até 5 dias úteis | I6: =IF(C6="Proposta em negociação","Obter PO, adjudicação ou data formal de decisão","Obter feedback e evolução do estado") -> Obter feedback e evolução do estado | J6: Pendente
A7: FINSTAR/ZAP | B7: Luísa Baltazar | C7: Proposta em negociação | D7: 21161250 | E7: Alta | F7: 5 | G7: =IF(OR(E7="Alta",D7>=10000000),"Contacto directo ao decisor e reunião de fecho",IF(F7>15,"Reactivar processo e solicitar decisão formal","Executar próxima acção e actualizar CRM")) -> Contacto directo ao decisor e reunião de fecho | H7: =IF(OR(E7="Alta",D7>=10000000),"48 horas","Até 5 dias úteis") -> 48 horas | I7: =IF(C7="Proposta em negociação","Obter PO, adjudicação ou data formal de decisão","Obter feedback e evolução do estado") -> Obter PO, adjudicação ou data formal de decisão | J7: Pendente
A8: CARPINANGOLA/CASAIS | B8: Luísa Baltazar | C8: Proposta aprovada | D8: 2017800 | E8: Alta | F8: 4 | G8: =IF(OR(E8="Alta",D8>=10000000),"Contacto directo ao decisor e reunião de fecho",IF(F8>15,"Reactivar processo e solicitar decisão formal","Executar próxima acção e actualizar CRM")) -> Contacto directo ao decisor e reunião de fecho | H8: =IF(OR(E8="Alta",D8>=10000000),"48 horas","Até 5 dias úteis") -> 48 horas | I8: =IF(C8="Proposta em negociação","Obter PO, adjudicação ou data formal de decisão","Obter feedback e evolução do estado") -> Obter feedback e evolução do estado | J8: Pendente
A9: CEGID/PRIMAVERA | B9: Luísa Baltazar | C9: Proposta aprovada | D9: 445700 | E9: Alta | F9: 2 | G9: =IF(OR(E9="Alta",D9>=10000000),"Contacto directo ao decisor e reunião de fecho",IF(F9>15,"Reactivar processo e solicitar decisão formal","Executar próxima acção e actualizar CRM")) -> Contacto directo ao decisor e reunião de fecho | H9: =IF(OR(E9="Alta",D9>=10000000),"48 horas","Até 5 dias úteis") -> 48 horas | I9: =IF(C9="Proposta em negociação","Obter PO, adjudicação ou data formal de decisão","Obter feedback e evolução do estado") -> Obter feedback e evolução do estado | J9: Pendente
A10: FINSTAR/ZAP | B10: Luísa Baltazar | C10: Proposta enviada | D10: 1966500 | E10: Normal | F10: 2 | G10: =IF(OR(E10="Alta",D10>=10000000),"Contacto directo ao decisor e reunião de fecho",IF(F10>15,"Reactivar processo e solicitar decisão formal","Executar próxima acção e actualizar CRM")) -> Executar próxima acção e actualizar CRM | H10: =IF(OR(E10="Alta",D10>=10000000),"48 horas","Até 5 dias úteis") -> Até 5 dias úteis | I10: =IF(C10="Proposta em negociação","Obter PO, adjudicação ou data formal de decisão","Obter feedback e evolução do estado") -> Obter feedback e evolução do estado | J10: Pendente
A11: SIAC | B11: Luísa Baltazar | C11: Proposta enviada | D11: 29641900 | E11: Normal | F11: 3 | G11: =IF(OR(E11="Alta",D11>=10000000),"Contacto directo ao decisor e reunião de fecho",IF(F11>15,"Reactivar processo e solicitar decisão formal","Executar próxima acção e actualizar CRM")) -> Contacto directo ao decisor e reunião de fecho | H11: =IF(OR(E11="Alta",D11>=10000000),"48 horas","Até 5 dias úteis") -> 48 horas | I11: =IF(C11="Proposta em negociação","Obter PO, adjudicação ou data formal de decisão","Obter feedback e evolução do estado") -> Obter feedback e evolução do estado | J11: Pendente
A12: SBM OFFSHORE | B12: Amélia Cassinda | C12: Proposta aprovada | D12: 339150 | E12: Normal | F12: 40 | G12: =IF(OR(E12="Alta",D12>=10000000),"Contacto directo ao decisor e reunião de fecho",IF(F12>15,"Reactivar processo e solicitar decisão formal","Executar próxima acção e actualizar CRM")) -> Reactivar processo e solicitar decisão formal | H12: =IF(OR(E12="Alta",D12>=10000000),"48 horas","Até 5 dias úteis") -> Até 5 dias úteis | I12: =IF(C12="Proposta em negociação","Obter PO, adjudicação ou data formal de decisão","Obter feedback e evolução do estado") -> Obter feedback e evolução do estado | J12: Pendente
A13: BCGA | B13: Amélia Cassinda | C13: Proposta aprovada | D13: 3135000 | E13: Alta | F13: 6 | G13: =IF(OR(E13="Alta",D13>=10000000),"Contacto directo ao decisor e reunião de fecho",IF(F13>15,"Reactivar processo e solicitar decisão formal","Executar próxima acção e actualizar CRM")) -> Contacto directo ao decisor e reunião de fecho | H13: =IF(OR(E13="Alta",D13>=10000000),"48 horas","Até 5 dias úteis") -> 48 horas | I13: =IF(C13="Proposta em negociação","Obter PO, adjudicação ou data formal de decisão","Obter feedback e evolução do estado") -> Obter feedback e evolução do estado | J13: Pendente
A14: TREVOTECH | B14: Amélia Cassinda | C14: Proposta aprovada | D14: 889200 | E14: Normal | F14: 6 | G14: =IF(OR(E14="Alta",D14>=10000000),"Contacto directo ao decisor e reunião de fecho",IF(F14>15,"Reactivar processo e solicitar decisão formal","Executar próxima acção e actualizar CRM")) -> Executar próxima acção e actualizar CRM | H14: =IF(OR(E14="Alta",D14>=10000000),"48 horas","Até 5 dias úteis") -> Até 5 dias úteis | I14: =IF(C14="Proposta em negociação","Obter PO, adjudicação ou data formal de decisão","Obter feedback e evolução do estado") -> Obter feedback e evolução do estado | J14: Pendente
A15: ANGOLACA | B15: Amélia Cassinda | C15: Proposta enviada | D15: 14248432 | E15: Média | F15: 2 | G15: =IF(OR(E15="Alta",D15>=10000000),"Contacto directo ao decisor e reunião de fecho",IF(F15>15,"Reactivar processo e solicitar decisão formal","Executar próxima acção e actualizar CRM")) -> Contacto directo ao decisor e reunião de fecho | H15: =IF(OR(E15="Alta",D15>=10000000),"48 horas","Até 5 dias úteis") -> 48 horas | I15: =IF(C15="Proposta em negociação","Obter PO, adjudicação ou data formal de decisão","Obter feedback e evolução do estado") -> Obter feedback e evolução do estado | J15: Pendente
A16: DUBAI INVESTIMETS | B16: Amélia Cassinda | C16: Proposta enviada | D16: 29724360 | E16: Média | F16: 5 | G16: =IF(OR(E16="Alta",D16>=10000000),"Contacto directo ao decisor e reunião de fecho",IF(F16>15,"Reactivar processo e solicitar decisão formal","Executar próxima acção e actualizar CRM")) -> Contacto directo ao decisor e reunião de fecho | H16: =IF(OR(E16="Alta",D16>=10000000),"48 horas","Até 5 dias úteis") -> 48 horas | I16: =IF(C16="Proposta em negociação","Obter PO, adjudicação ou data formal de decisão","Obter feedback e evolução do estado") -> Obter feedback e evolução do estado | J16: Pendente
... A36: BAXTTER | B36: Fernando Leite | C36: Proposta aprovada | D36: 444600 | E36: Normal | F36: 4 | G36: =IF(OR(E36="Alta",D36>=10000000),"Contacto directo ao decisor e reunião de fecho",IF(F36>15,"Reactivar processo e solicitar decisão formal","Executar próxima acção e actualizar CRM")) -> Executar próxima acção e actualizar CRM | H36: =IF(OR(E36="Alta",D36>=10000000),"48 horas","Até 5 dias úteis") -> Até 5 dias úteis | I36: =IF(C36="Proposta em negociação","Obter PO, adjudicação ou data formal de decisão","Obter feedback e evolução do estado") -> Obter feedback e evolução do estado | J36: Pendente

Sheet Comparativo
A1: COMPARATIVO DAS DUAS SEMANAS
A4: Indicador | B4: 06–10 Jul | C4: 13–17 Jul | D4: Variação | E4: Leitura
A5: N.º de propostas | B5: =COUNTIF(Base_Duas_Semanas!$A$4:$A$464,"Semana Anterior") -> 29 | C5: =COUNTIF(Base_Duas_Semanas!$A$4:$A$464,"Semana Finda") -> 32 | D5: =IFERROR((C5-B5)/B5,0) -> 0.10344828 | E5: =IF(D5>0,"Mais propostas",IF(D5<0,"Menos propostas","Estável")) -> Mais propostas
A6: Valor total | B6: =SUMIF(Base_Duas_Semanas!$A$4:$A$464,"Semana Anterior",Base_Duas_Semanas!$G$4:$G$464) -> 1.5028229e+08 | C6: =SUMIF(Base_Duas_Semanas!$A$4:$A$464,"Semana Finda",Base_Duas_Semanas!$G$4:$G$464) -> 2.6345043e+08 | D6: =IFERROR((C6-B6)/B6,0) -> 0.75303716 | E6: =IF(D6>0,"Crescimento",IF(D6<0,"Redução","Estável")) -> Crescimento
A7: Valor aprovado | B7: =SUMIF(Base_Duas_Semanas!$A$2:$A$464,"Semana Anterior",Base_Duas_Semanas!$H$2:$H$464) -> 19914950 | C7: =SUMIF(Base_Duas_Semanas!$A$2:$A$464,"Semana Finda",Base_Duas_Semanas!$H$2:$H$464) -> 26762350 | D7: =IFERROR((C7-B7)/B7,0) -> 0.34383215 | E7: =IF(D7>0,"Melhoria",IF(D7<0,"Redução","Estável")) -> Melhoria
A8: Valor perdido | B8: =SUMIF(Base_Duas_Semanas!$A$2:$A$464,"Semana Anterior",Base_Duas_Semanas!$I$2:$I$464) -> 11779700 | C8: =SUMIFS(Base_Duas_Semanas!$I$2:$I$464,Base_Duas_Semanas!$A$2:$A$464,"Semana Finda") -> 11712075 | D8: =IFERROR(C8/B8-1,0) -> -0.0057408083 | E8: =IF(AND(B8=0,C8>0),"Atenção: surgiram perdas",IF(D8>0,"Atenção: aumentou",IF(D8<0,"Melhoria: reduziu","Estável"))) -> Melhoria: reduziu
A9: Forecast | B9: =SUMIF(Base_Duas_Semanas!$A$2:$A$464,"Semana Anterior",Base_Duas_Semanas!$P$2:$P$464) -> 76353142 | C9: =SUMIF(Base_Duas_Semanas!$A$4:$A$464,"Semana Finda",Base_Duas_Semanas!$P$4:$P$464) -> 1.2311572e+08 | D9: =IFERROR((C9-B9)/B9,0) -> 0.61245129 | E9: =IF(D9>0,"Melhoria",IF(D9<0,"Redução","Estável")) -> Melhoria
A10: Conversão | B10: =IFERROR(B7/B6,0) -> 0.13251695 | C10: =IFERROR(C7/C6,0) -> 0.10158401 | D10: =IFERROR((C10-B10)/B10,0) -> -0.23342632 | E10: =IF(D10>0,"Melhoria",IF(D10<0,"Redução","Estável")) -> Redução
A11: Ticket médio | B11: =IFERROR(B6/B5,0) -> 5182147.8 | C11: =IFERROR(C6/C5,0) -> 8232826 | D11: =IFERROR((C11-B11)/B11,0) -> 0.58868993 | E11: =IF(D11>0,"Aumento",IF(D11<0,"Redução","Estável")) -> Aumento

Sheet Listas
A1: Comerciais | B1: Estados | C1: Probabilidade | D1: Prioridade | E1: Estado CRM | G1: Gestor Comercial | H1: Função | I1: Meta Mensal | J1: Meta Semanal | K1: Comissão % | L1: Peso Conversão | M1: Meta Sem. Actualizada | N1: Observações
A2: Amélia Cassinda | B2: Proposta enviada | C2: 0 | D2: Alta | E2: Aberto | G2: Amélia Cassinda | H2: Sénior | I2: 25000000 | J2: 6250000 | K2: 0.03 | L2: 0.4 | M2: 6250000 | N2: Meta actualizada a conjugar com comparativo semanal
A3: David Guedes | B3: Proposta em negociação | C3: 0.2 | D3: Média | E3: Fechado ganho | G3: David Guedes | H3: Comercial | I3: 15000000 | J3: 3750000 | K3: 0.03 | L3: 0.4 | M3: 3750000 | N3: Meta actualizada a conjugar com comparativo semanal
A4: Fernando Leite | B4: Proposta aprovada | C4: 0.3 | D4: Normal | E4: Fechado perdido | G4: Fernando Leite | H4: Comercial | I4: 10000000 | J4: 2500000 | K4: 0.03 | L4: 0.4 | M4: 2500000 | N4: Meta actualizada a conjugar com comparativo semanal
A5: José Neto | B5: Produção / Entrega | C5: 0.4 | D5: Baixa | G5: José Neto | H5: Sénior | I5: 20000000 | J5: 5000000 | K5: 0.03 | L5: 0.4 | M5: 5000000 | N5: Meta actualizada a conjugar com comparativo semanal
A6: Marta de Oliveira | B6: Perdida | C6: 0.5 | G6: Marta de Oliveira | H6: Sénior | I6: 25000000 | J6: 6250000 | K6: 0.03 | L6: 0.4 | M6: 6250000 | N6: Meta actualizada a conjugar com comparativo semanal
A7: Ilídio Pedro | C7: 0.6 | G7: Ilídio Pedro | H7: Comercial | I7: 10000000 | J7: 2500000 | K7: 0.03 | L7: 0.4 | M7: 2500000 | N7: Meta actualizada a conjugar com comparativo semanal
A8: Luísa Baltazar | C8: 0.7 | G8: Luísa Baltazar | H8: Sénior EDGER | I8: 30000000 | J8: 7500000 | K8: 0.03 | L8: 0.4 | M8: 7500000 | N8: Meta actualizada a conjugar com comparativo semanal
C9: 0.8
C10: 0.9
C11: 1

Sheet Manual
A1: MANUAL RÁPIDO – DASHBOARD COMERCIAL V5.0
A4: Passo | B4: Como utilizar
A5: 1 | B5: Preencher novas propostas na folha Base_Duas_Semanas, uma proposta por linha.
A6: 2 | B6: Usar as listas suspensas para Estado, Probabilidade, Comercial, Prioridade e Estado CRM.
A7: 3 | B7: No início de uma nova semana, alterar os registos anteriores para Semana Anterior e inserir os novos como Semana Finda.
A8: 4 | B8: As metas semanais são preenchidas automaticamente a partir da V7.0.
A9: 5 | B9: Consultar o Dashboard_V5 para KPIs, gráficos, comparativo e metas.
A10: 6 | B10: Consultar CRM_Proxima_Semana e actualizar o acompanhamento de cada cliente.

Sheet Resumo_Executivo
A1: ANÁLISE CRÍTICA COMERCIAL — 13 A 17 DE JULHO DE 2026 | B1: ANÁLISE CRÍTICA COMERCIAL — 13 A 17 DE JULHO DE 2026 | C1: ANÁLISE CRÍTICA COMERCIAL — 13 A 17 DE JULHO DE 2026 | D1: ANÁLISE CRÍTICA COMERCIAL — 13 A 17 DE JULHO DE 2026 | E1: ANÁLISE CRÍTICA COMERCIAL — 13 A 17 DE JULHO DE 2026 | F1: ANÁLISE CRÍTICA COMERCIAL — 13 A 17 DE JULHO DE 2026 | G1: ANÁLISE CRÍTICA COMERCIAL — 13 A 17 DE JULHO DE 2026 | H1: ANÁLISE CRÍTICA COMERCIAL — 13 A 17 DE JULHO DE 2026 | I1: ANÁLISE CRÍTICA COMERCIAL — 13 A 17 DE JULHO DE 2026 | J1: ANÁLISE CRÍTICA COMERCIAL — 13 A 17 DE JULHO DE 2026 | K1: ANÁLISE CRÍTICA COMERCIAL — 13 A 17 DE JULHO DE 2026 | L1: ANÁLISE CRÍTICA COMERCIAL — 13 A 17 DE JULHO DE 2026
A2: GPA ANGOLA | Relatório executivo integrado | Valores em AOA | Elaborado em 20-07-2026 | B2: GPA ANGOLA | Relatório executivo integrado | Valores em AOA | Elaborado em 20-07-2026 | C2: GPA ANGOLA | Relatório executivo integrado | Valores em AOA | Elaborado em 20-07-2026 | D2: GPA ANGOLA | Relatório executivo integrado | Valores em AOA | Elaborado em 20-07-2026 | E2: GPA ANGOLA | Relatório executivo integrado | Valores em AOA | Elaborado em 20-07-2026 | F2: GPA ANGOLA | Relatório executivo integrado | Valores em AOA | Elaborado em 20-07-2026 | G2: GPA ANGOLA | Relatório executivo integrado | Valores em AOA | Elaborado em 20-07-2026 | H2: GPA ANGOLA | Relatório executivo integrado | Valores em AOA | Elaborado em 20-07-2026 | I2: GPA ANGOLA | Relatório executivo integrado | Valores em AOA | Elaborado em 20-07-2026 | J2: GPA ANGOLA | Relatório executivo integrado | Valores em AOA | Elaborado em 20-07-2026 | K2: GPA ANGOLA | Relatório executivo integrado | Valores em AOA | Elaborado em 20-07-2026 | L2: GPA ANGOLA | Relatório executivo integrado | Valores em AOA | Elaborado em 20-07-2026
A4: 1. INDICADORES-CHAVE DA SEMANA | B4: 1. INDICADORES-CHAVE DA SEMANA | C4: 1. INDICADORES-CHAVE DA SEMANA | D4: 1. INDICADORES-CHAVE DA SEMANA | E4: 1. INDICADORES-CHAVE DA SEMANA | F4: 1. INDICADORES-CHAVE DA SEMANA | G4: 1. INDICADORES-CHAVE DA SEMANA | H4: 1. INDICADORES-CHAVE DA SEMANA | I4: 1. INDICADORES-CHAVE DA SEMANA | J4: 1. INDICADORES-CHAVE DA SEMANA | K4: 1. INDICADORES-CHAVE DA SEMANA | L4: 1. INDICADORES-CHAVE DA SEMANA
A5: Propostas | C5: Valor proposto | E5: Valor aprovado | G5: Conversão | I5: Pipeline aberto | K5: Forecast ponderado
A6: =COUNTIF(Base_Duas_Semanas!$A$2:$A$464,"Semana Finda") -> 32 | C6: =SUMIFS(Base_Duas_Semanas!$G$2:$G$464,Base_Duas_Semanas!$A$2:$A$464,"Semana Finda") -> 2.6345043e+08 | E6: =SUMIFS(Base_Duas_Semanas!$H$2:$H$464,Base_Duas_Semanas!$A$2:$A$464,"Semana Finda") -> 26762350 | G6: =IFERROR(E6/C6,0) -> 0.10158401 | I6: =SUMIFS(Base_Duas_Semanas!$G$2:$G$464,Base_Duas_Semanas!$A$2:$A$464,"Semana Finda",Base_Duas_Semanas!$S$2:$S$464,"Aberto") -> 2.2497601e+08 | K6: =SUMIFS(Base_Duas_Semanas!$P$2:$P$464,Base_Duas_Semanas!$A$2:$A$464,"Semana Finda") -> 1.2311572e+08
A9: 2. COMPARATIVO SEMANAL | B9: 2. COMPARATIVO SEMANAL | C9: 2. COMPARATIVO SEMANAL | D9: 2. COMPARATIVO SEMANAL | E9: 2. COMPARATIVO SEMANAL | F9: 2. COMPARATIVO SEMANAL | G9: 3. LEITURA EXECUTIVA | H9: 3. LEITURA EXECUTIVA | I9: 3. LEITURA EXECUTIVA | J9: 3. LEITURA EXECUTIVA | K9: 3. LEITURA EXECUTIVA | L9: 3. LEITURA EXECUTIVA
A10: Indicador | B10: 06–10 Jul | C10: 13–17 Jul | D10: Variação | G10: A actividade comercial aumentou em quantidade e valor, mas a conversão permanece baixa face à dimensão do pipeline. A semana gerou 32 propostas, 263,45 milhões AOA de valor proposto e 26,76 milhões AOA aprovados. O crescimento está fortemente concentrado em UNITEL e na carteira de Luísa Baltazar. Ilídio Pedro e Marta de Oliveira superaram as metas semanais; cinco dos sete comerciais ficaram abaixo de 70%. O forecast ponderado de 123,12 milhões AOA deve ser tratado como potencial condicionado, não como receita assegurada. Prioridade de gestão: converter as oportunidades de alta probabilidade, formalizar PO/adjudicações e eliminar registos sem próxima acção, decisor e data de fecho.
A11: N.º de propostas | B11: =COUNTIF(Base_Duas_Semanas!$A$2:$A$464,"Semana Anterior") -> 31 | C11: =COUNTIF(Base_Duas_Semanas!$A$2:$A$464,"Semana Finda") -> 32 | D11: =IFERROR(C11/B11-1,0) -> 0.032258065
A12: Valor proposto | B12: =SUMIFS(Base_Duas_Semanas!$G$2:$G$464,Base_Duas_Semanas!$A$2:$A$464,"Semana Anterior") -> 1.5792827e+08 | C12: =SUMIFS(Base_Duas_Semanas!$G$2:$G$464,Base_Duas_Semanas!$A$2:$A$464,"Semana Finda") -> 2.6345043e+08 | D12: =IFERROR(C12/B12-1,0) -> 0.66816516
A13: Valor aprovado | B13: =SUMIFS(Base_Duas_Semanas!$H$2:$H$464,Base_Duas_Semanas!$A$2:$A$464,"Semana Anterior") -> 19914950 | C13: =SUMIFS(Base_Duas_Semanas!$H$2:$H$464,Base_Duas_Semanas!$A$2:$A$464,"Semana Finda") -> 26762350 | D13: =IFERROR(C13/B13-1,0) -> 0.34383215
A14: Valor perdido | B14: =SUMIFS(Base_Duas_Semanas!$I$2:$I$464,Base_Duas_Semanas!$A$2:$A$464,"Semana Anterior") -> 11779700 | C14: =SUMIFS(Base_Duas_Semanas!$I$2:$I$464,Base_Duas_Semanas!$A$2:$A$464,"Semana Finda") -> 11712075 | D14: =IFERROR(C14/B14-1,0) -> -0.0057408083
A15: Forecast ponderado | B15: =SUMIFS(Base_Duas_Semanas!$P$2:$P$464,Base_Duas_Semanas!$A$2:$A$464,"Semana Anterior") -> 76353142 | C15: =SUMIFS(Base_Duas_Semanas!$P$2:$P$464,Base_Duas_Semanas!$A$2:$A$464,"Semana Finda") -> 1.2311572e+08 | D15: =IFERROR(C15/B15-1,0) -> 0.61245129
A16: Conversão | B16: =IFERROR(B13/B12,0) -> 0.12610124 | C16: =IFERROR(C13/C12,0) -> 0.10158401 | D16: =IFERROR(C16/B16-1,0) -> -0.194425
A17: Ticket médio | B17: =IFERROR(B12/B11,0) -> 5094460.2 | C17: =IFERROR(C12/C11,0) -> 8232826 | D17: =IFERROR(C17/B17-1,0) -> 0.616035
A19: 4. PERFORMANCE POR COMERCIAL | B19: 4. PERFORMANCE POR COMERCIAL | C19: 4. PERFORMANCE POR COMERCIAL | D19: 4. PERFORMANCE POR COMERCIAL | E19: 4. PERFORMANCE POR COMERCIAL | F19: 4. PERFORMANCE POR COMERCIAL | G19: 4. PERFORMANCE POR COMERCIAL | H19: 4. PERFORMANCE POR COMERCIAL | I19: 4. PERFORMANCE POR COMERCIAL | J19: 4. PERFORMANCE POR COMERCIAL | K19: 4. PERFORMANCE POR COMERCIAL | L19: 4. PERFORMANCE POR COMERCIAL
A20: Comercial | B20: Meta semanal | C20: Propostas | D20: Valor proposto | E20: Aprovado | F20: % Meta | G20: Pipeline aberto | H20: Forecast | I20: Diagnóstico | K20: Comercial | L20: % Meta
A21: Amélia Cassinda | B21: =Metas_Performance!C5 -> 6250000 | C21: =Metas_Performance!D5 -> 6 | D21: =Metas_Performance!E5 -> 51919142 | E21: =Metas_Performance!F5 -> 4363350 | F21: =Metas_Performance!G5 -> 0.698136 | G21: =Metas_Performance!H5 -> 47555792 | H21: =Metas_Performance!I5 -> 24810510 | I21: Bom volume; focar ANGOLACA e DUBAI, com proposta de valor e data de decisão. | K21: =A21 -> Amélia Cassinda | L21: =F21 -> 0.698136
A22: David Guedes | B22: =Metas_Performance!C6 -> 3750000 | C22: =Metas_Performance!D6 -> 5 | D22: =Metas_Performance!E6 -> 8261979 | E22: =Metas_Performance!F6 -> 0 | F22: =Metas_Performance!G6 -> 0 | G22: =Metas_Performance!H6 -> 8261979 | H22: =Metas_Performance!I6 -> 3814018.2 | I22: Sem aprovações; escalar DP WORLD e validar decisor, orçamento, urgência e amostra. | K22: =A22 -> David Guedes | L22: =F22 -> 0
A23: Fernando Leite | B23: =Metas_Performance!C7 -> 2500000 | C23: =Metas_Performance!D7 -> 3 | D23: =Metas_Performance!E7 -> 14915475 | E23: =Metas_Performance!F7 -> 444600 | F23: =Metas_Performance!G7 -> 0.17784 | G23: =Metas_Performance!H7 -> 6002100 | H23: =Metas_Performance!I7 -> 2845440 | I23: Baixa conversão; recuperar GRUPO CASTEL e documentar causa de perda de 5 LINHAS. | K23: =A23 -> Fernando Leite | L23: =F23 -> 0.17784
A24: Ilídio Pedro | B24: =Metas_Performance!C8 -> 2500000 | C24: =Metas_Performance!D8 -> 3 | D24: =Metas_Performance!E8 -> 11220450 | E24: =Metas_Performance!F8 -> 7977150 | F24: =Metas_Performance!G8 -> 3.19086 | G24: =Metas_Performance!H8 -> 0 | H24: =Metas_Performance!I8 -> 7977150 | I24: Melhor execução da semana; proteger margem e assegurar entrega/facturação SONANGOL. | K24: =A24 -> Ilídio Pedro | L24: =F24 -> 3.19086
A25: José Neto | B25: =Metas_Performance!C9 -> 5000000 | C25: =Metas_Performance!D9 -> 3 | D25: =Metas_Performance!E9 -> 4794498 | E25: =Metas_Performance!F9 -> 0 | F25: =Metas_Performance!G9 -> 0 | G25: =Metas_Performance!H9 -> 4794498 | H25: =Metas_Performance!I9 -> 1917799.2 | I25: Sem aprovações; requalificar BNI, PRODEL e TOPACK antes de conceder desconto. | K25: =A25 -> José Neto | L25: =F25 -> 0
A26: Luísa Baltazar | B26: =Metas_Performance!C10 -> 7500000 | C26: =Metas_Performance!D10 -> 7 | D26: =Metas_Performance!E10 -> 153045150 | E26: =Metas_Performance!F10 -> 4150700 | F26: =Metas_Performance!G10 -> 0.55342667 | G26: =Metas_Performance!H10 -> 148894450 | H26: =Metas_Performance!I10 -> 68137380 | I26: Maior carteira e forte concentração; fechar ZAP e obter contraproposta formal UNITEL. | K26: =A26 -> Luísa Baltazar | L26: =F26 -> 0.55342667
A27: Marta de Oliveira | B27: =Metas_Performance!C11 -> 6250000 | C27: =Metas_Performance!D11 -> 5 | D27: =Metas_Performance!E11 -> 19293737 | E27: =Metas_Performance!F11 -> 9826550 | F27: =Metas_Performance!G11 -> 1.572248 | G27: =Metas_Performance!H11 -> 9467187 | H27: =Metas_Performance!I11 -> 13613425 | I27: Meta superada; converter PROGRAMA ALIMENTAR e ATO, mantendo controlo de produção. | K27: =A27 -> Marta de Oliveira | L27: =F27 -> 1.572248

Sheet Alinhamento_Financeiro
A1: ALINHAMENTO FINANCEIRO E QUALIDADE DO PIPELINE | B1: ALINHAMENTO FINANCEIRO E QUALIDADE DO PIPELINE | C1: ALINHAMENTO FINANCEIRO E QUALIDADE DO PIPELINE | D1: ALINHAMENTO FINANCEIRO E QUALIDADE DO PIPELINE | E1: ALINHAMENTO FINANCEIRO E QUALIDADE DO PIPELINE | F1: ALINHAMENTO FINANCEIRO E QUALIDADE DO PIPELINE | G1: ALINHAMENTO FINANCEIRO E QUALIDADE DO PIPELINE | H1: ALINHAMENTO FINANCEIRO E QUALIDADE DO PIPELINE | I1: ALINHAMENTO FINANCEIRO E QUALIDADE DO PIPELINE | J1: ALINHAMENTO FINANCEIRO E QUALIDADE DO PIPELINE
A2: Reconciliação entre propostas, aprovações, perdas, pipeline e forecast ponderado | B2: Reconciliação entre propostas, aprovações, perdas, pipeline e forecast ponderado | C2: Reconciliação entre propostas, aprovações, perdas, pipeline e forecast ponderado | D2: Reconciliação entre propostas, aprovações, perdas, pipeline e forecast ponderado | E2: Reconciliação entre propostas, aprovações, perdas, pipeline e forecast ponderado | F2: Reconciliação entre propostas, aprovações, perdas, pipeline e forecast ponderado | G2: Reconciliação entre propostas, aprovações, perdas, pipeline e forecast ponderado | H2: Reconciliação entre propostas, aprovações, perdas, pipeline e forecast ponderado | I2: Reconciliação entre propostas, aprovações, perdas, pipeline e forecast ponderado | J2: Reconciliação entre propostas, aprovações, perdas, pipeline e forecast ponderado
A4: 1. PONTE FINANCEIRA — SEMANA DE 13 A 17 DE JULHO | B4: 1. PONTE FINANCEIRA — SEMANA DE 13 A 17 DE JULHO | C4: 1. PONTE FINANCEIRA — SEMANA DE 13 A 17 DE JULHO | D4: 1. PONTE FINANCEIRA — SEMANA DE 13 A 17 DE JULHO | E4: 1. PONTE FINANCEIRA — SEMANA DE 13 A 17 DE JULHO | F4: 1. PONTE FINANCEIRA — SEMANA DE 13 A 17 DE JULHO | G4: 1. PONTE FINANCEIRA — SEMANA DE 13 A 17 DE JULHO | H4: 1. PONTE FINANCEIRA — SEMANA DE 13 A 17 DE JULHO | I4: 1. PONTE FINANCEIRA — SEMANA DE 13 A 17 DE JULHO | J4: 1. PONTE FINANCEIRA — SEMANA DE 13 A 17 DE JULHO
A5: Métrica | B5: Valor | C5: % do valor proposto | D5: Critério | E5: Leitura de gestão
A6: Valor proposto | B6: =Resumo_Executivo!C6 -> 2.6345043e+08 | C6: =1 -> 1 | D6: Base bruta | E6: Volume elevado, mas muito dependente de poucas propostas.
A7: Valor aprovado | B7: =Resumo_Executivo!E6 -> 26762350 | C7: =IFERROR(B7/B6,0) -> 0.10158401 | D7: Receita comercial contratada/ganha | E7: Conversão financeira de apenas cerca de 10%; exige foco em fecho.
A8: Valor perdido | B8: =Resumo_Executivo!C14 -> 11712075 | C8: =IFERROR(B8/B6,0) -> 0.044456465 | D8: Oportunidades encerradas sem ganho | E8: Inclui a correcção de 5 LINHAS, anteriormente omitida em Valor perdido.
A9: Pipeline aberto | B9: =Resumo_Executivo!I6 -> 2.2497601e+08 | C9: =IFERROR(B9/B6,0) -> 0.85395953 | D9: Oportunidades ainda abertas | E9: É o principal activo comercial, mas ainda sem garantia de receita.
A10: Forecast ponderado | B10: =Resumo_Executivo!K6 -> 1.2311572e+08 | C10: =IFERROR(B10/B6,0) -> 0.46732025 | D10: Valor × probabilidade | E10: Não deve ser confundido com facturação nem tesouraria disponível.
A11: Gap para converter pipeline | B11: =B9-B10 -> 1.0186028e+08 | C11: =IFERROR(B11/B6,0) -> 0.38663928 | D11: Pipeline não coberto pelo forecast | E11: Montante que depende de melhoria de probabilidade, condições e decisão.
A12: Cobertura do forecast / meta equipa | B12: =IFERROR(B10/SUM(Metas_Performance!C5:C11),0) -> 3.6478733 | D12: Forecast vs meta semanal agregada | E12: Cobertura potencial confortável, porém com risco de concentração.
A14: 2. CONCENTRAÇÃO E RISCO COMERCIAL | B14: 2. CONCENTRAÇÃO E RISCO COMERCIAL | C14: 2. CONCENTRAÇÃO E RISCO COMERCIAL | D14: 2. CONCENTRAÇÃO E RISCO COMERCIAL | E14: 2. CONCENTRAÇÃO E RISCO COMERCIAL | F14: 2. CONCENTRAÇÃO E RISCO COMERCIAL | G14: 2. CONCENTRAÇÃO E RISCO COMERCIAL | H14: 2. CONCENTRAÇÃO E RISCO COMERCIAL | I14: 2. CONCENTRAÇÃO E RISCO COMERCIAL | J14: 2. CONCENTRAÇÃO E RISCO COMERCIAL
A15: Indicador de risco | B15: Cálculo | C15: Resultado | D15: Sinal | E15: Acção recomendada
A16: Peso da UNITEL no valor proposto | B16: UNITEL / valor proposto | C16: =IFERROR(SUMIFS(Base_Duas_Semanas!$G$2:$G$464,Base_Duas_Semanas!$A$2:$A$464,"Semana Finda",Base_Duas_Semanas!$D$2:$D$464,"UNITEL")/Resumo_Executivo!C6,0) -> 0.36486864 | D16: Alto | E16: Preparar negociação por cenários e evitar dependência de uma única adjudicação.
A17: Peso da Luísa no valor proposto | B17: Carteira Luísa / valor proposto | C17: =IFERROR(SUMIFS(Base_Duas_Semanas!$G$2:$G$464,Base_Duas_Semanas!$A$2:$A$464,"Semana Finda",Base_Duas_Semanas!$K$2:$K$464,"Luísa Baltazar")/Resumo_Executivo!C6,0) -> 0.58092579 | D17: Alto | E17: Distribuir prospecção e coaching para elevar a contribuição dos restantes comerciais.
A18: Comerciais sem aprovações | B18: Contagem de % meta = 0 | C18: =COUNTIF(Metas_Performance!$G$5:$G$11,0) -> 2 | D18: Crítico | E18: Plano diário de recuperação, com qualificação e reunião acompanhada.
A19: Propostas abertas de prioridade alta | B19: Prioridade Alta + CRM Aberto | C19: =COUNTIFS(Base_Duas_Semanas!$A$2:$A$464,"Semana Finda",Base_Duas_Semanas!$R$2:$R$464,"Alta",Base_Duas_Semanas!$S$2:$S$464,"Aberto") -> 6 | D19: Prioritário | E19: Contacto com decisor em 48h, data formal de decisão e próximo passo no CRM.
A20: Registos perdidos com causa documentada | B20: Revisão obrigatória pós-perda | C20: 2 | D20: A melhorar | E20: Registar concorrente, preço, prazo, qualidade, relação e lição aprendida.
A22: 3. CONTROLos DE RECONCILIAÇÃO | B22: 3. CONTROLos DE RECONCILIAÇÃO | C22: 3. CONTROLos DE RECONCILIAÇÃO | D22: 3. CONTROLos DE RECONCILIAÇÃO | E22: 3. CONTROLos DE RECONCILIAÇÃO | F22: 3. CONTROLos DE RECONCILIAÇÃO | G22: 3. CONTROLos DE RECONCILIAÇÃO | H22: 3. CONTROLos DE RECONCILIAÇÃO | I22: 3. CONTROLos DE RECONCILIAÇÃO | J22: 3. CONTROLos DE RECONCILIAÇÃO
A23: Controlo | B23: Resultado | C23: Estado | D23: Observação
